<?xml version="1.0" ?>
<robot name="trial" xmlns:xacro="http://www.ros.org/wiki/xacro">

<xacro:include filename="$(find trial_description)/urdf/materials.xacro" />
<xacro:include filename="$(find trial_description)/urdf/trial.trans" />
<xacro:include filename="$(find trial_description)/urdf/trial.gazebo" />
<link name="base_link">
  <inertial>
    <origin rpy="0 0 0" xyz="0.00024515429005832244 0.0 0.003649472912835996"/>
    <mass value="0.002213483451648013"/>
    <inertia ixx="0.0" ixy="0.0" ixz="-0.0" iyy="0.0" iyz="0.0" izz="0.0"/>
  </inertial>
  <visual>
    <origin rpy="0 0 0" xyz="0 0 0"/>
    <geometry>
      <mesh filename="package://trial_description/meshes/base_link.stl" scale="0.001 0.001 0.001"/>
    </geometry>
    <material name="silver"/>
  </visual>
  <collision>
    <origin rpy="0 0 0" xyz="0 0 0"/>
    <geometry>
      <mesh filename="package://trial_description/meshes/base_link.stl" scale="0.001 0.001 0.001"/>
    </geometry>
  </collision>
</link>

<link name="left_wheel_1">
  <inertial>
    <origin rpy="0 0 0" xyz="3.6598869835286766e-13 0.0010000000000000009 -8.673617379884035e-19"/>
    <mass value="7.158119226910766e-05"/>
    <inertia ixx="0.0" ixy="0.0" ixz="-0.0" iyy="0.0" iyz="0.0" izz="0.0"/>
  </inertial>
  <visual>
    <origin rpy="0 0 0" xyz="-0.0 -0.01 -0.0035"/>
    <geometry>
      <mesh filename="package://trial_description/meshes/left_wheel_1.stl" scale="0.001 0.001 0.001"/>
    </geometry>
    <material name="silver"/>
  </visual>
  <collision>
    <origin rpy="0 0 0" xyz="-0.0 -0.01 -0.0035"/>
    <geometry>
      <mesh filename="package://trial_description/meshes/left_wheel_1.stl" scale="0.001 0.001 0.001"/>
    </geometry>
  </collision>
</link>

<link name="right_wheel_1">
  <inertial>
    <origin rpy="0 0 0" xyz="3.6598869835286766e-13 -0.0010000000000000009 -8.673617379884035e-19"/>
    <mass value="7.158119226910766e-05"/>
    <inertia ixx="0.0" ixy="0.0" ixz="-0.0" iyy="0.0" iyz="-0.0" izz="0.0"/>
  </inertial>
  <visual>
    <origin rpy="0 0 0" xyz="-0.0 0.01 -0.0035"/>
    <geometry>
      <mesh filename="package://trial_description/meshes/right_wheel_1.stl" scale="0.001 0.001 0.001"/>
    </geometry>
    <material name="silver"/>
  </visual>
  <collision>
    <origin rpy="0 0 0" xyz="-0.0 0.01 -0.0035"/>
    <geometry>
      <mesh filename="package://trial_description/meshes/right_wheel_1.stl" scale="0.001 0.001 0.001"/>
    </geometry>
  </collision>
</link>

<link name="lidar_1">
  <inertial>
    <origin rpy="0 0 0" xyz="1.040989933143166e-10 3.4511225983891793e-19 0.0010000000000000026"/>
    <mass value="3.468318392927219e-05"/>
    <inertia ixx="0.0" ixy="0.0" ixz="0.0" iyy="0.0" iyz="-0.0" izz="0.0"/>
  </inertial>
  <visual>
    <origin rpy="0 0 0" xyz="-0.007 -0.0 -0.011"/>
    <geometry>
      <mesh filename="package://trial_description/meshes/lidar_1.stl" scale="0.001 0.001 0.001"/>
    </geometry>
    <material name="silver"/>
  </visual>
  <collision>
    <origin rpy="0 0 0" xyz="-0.007 -0.0 -0.011"/>
    <geometry>
      <mesh filename="package://trial_description/meshes/lidar_1.stl" scale="0.001 0.001 0.001"/>
    </geometry>
  </collision>
</link>

<joint name="Rev1" type="continuous">
  <origin rpy="0 0 0" xyz="0.0 0.01 0.0035"/>
  <parent link="base_link"/>
  <child link="left_wheel_1"/>
  <axis xyz="0.0 1.0 0.0"/>
</joint>

<joint name="Rev2" type="continuous">
  <origin rpy="0 0 0" xyz="0.0 -0.01 0.0035"/>
  <parent link="base_link"/>
  <child link="right_wheel_1"/>
  <axis xyz="0.0 -1.0 0.0"/>
</joint>

<joint name="Rigid3" type="fixed">
  <origin rpy="0 0 0" xyz="0.007 0.0 0.011"/>
  <parent link="base_link"/>
  <child link="lidar_1"/>
</joint>

</robot>
